Workbook

Sheet TOTAL EM ABERTO
A1: Codigo PN | B1: Razao Social | C1: No.Docto. | D1: No. NF | E1: Emissão | F1: Vencimento | G1: Valor R$ | H1: Dias Atraso | I1: Observacoes | J1: Vendedor | K1: Forma Pagto.
A2: CL08007 | B2: CONTINENTAL AGRONEGOCIOS EIRELI ME | C2: 20750 | D2: 29860 | E2: 44844 | F2: 45076 | G2: 296573.94 | H2: 673 | I2: NOTA FISCAL Nº 29860 | J2: CLAYRTON DA SILVA | K2: BRASIL_COB
A3: CL08007 | B3: CONTINENTAL AGRONEGOCIOS EIRELI ME | C3: 20867 | D3: 29996 | E3: 44858 | F3: 45076 | G3: 104000 | H3: 673 | I3: NOTA FISCAL Nº 29996 | J3: CLAYRTON DA SILVA | K3: BRASIL_COB
A4: CL08007 | B4: CONTINENTAL AGRONEGOCIOS EIRELI ME | C4: 20847 | D4: 29968 | E4: 44854 | F4: 45076 | G4: 67036.32 | H4: 673 | I4: NOTA FISCAL Nº 29968 | J4: CLAYRTON DA SILVA | K4: BRASIL_COB
A5: CL08007 | B5: CONTINENTAL AGRONEGOCIOS EIRELI ME | C5: 21739 | D5: 30890 | E5: 44961 | F5: 45168 | G5: 22000 | H5: 581 | I5: NOTA FISCAL Nº 30890 | J5: CLAYRTON DA SILVA | K5: BRASIL_COB
A6: CL08007 | B6: CONTINENTAL AGRONEGOCIOS EIRELI ME | C6: 21546 | D6: 30701 | E6: 44944 | F6: 45168 | G6: 15600 | H6: 581 | I6: NOTA FISCAL Nº 30701 | J6: CLAYRTON DA SILVA | K6: BRASIL_COB
A7: CL08007 | B7: CONTINENTAL AGRONEGOCIOS EIRELI ME | C7: 21379 | D7: 30540 | E7: 44921 | F7: 45168 | G7: 248695 | H7: 581 | I7: NOTA FISCAL Nº 30540 | J7: CLAYRTON DA SILVA | K7: BRASIL_COB
A8: CL08007 | B8: CONTINENTAL AGRONEGOCIOS EIRELI ME | C8: 21617 | D8: 30775 | E8: 44950 | F8: 45168 | G8: 353500 | H8: 581 | I8: NOTA FISCAL Nº 30775 | J8: CLAYRTON DA SILVA | K8: BRASIL_COB
A9: CL08007 | B9: CONTINENTAL AGRONEGOCIOS EIRELI ME | C9: 21616 | D9: 30774 | E9: 44950 | F9: 45199 | G9: 335040 | H9: 550 | I9: NOTA FISCAL Nº 30774 | J9: CLAYRTON DA SILVA | K9: BRASIL_COB
A10: CL08007 | B10: CONTINENTAL AGRONEGOCIOS EIRELI ME | C10: 21740 | D10: 30891 | E10: 44961 | F10: 45199 | G10: 168960 | H10: 550 | I10: NOTA FISCAL Nº 30891 | J10: CLAYRTON DA SILVA | K10: BRASIL_COB
A11: CL08007 | B11: CONTINENTAL AGRONEGOCIOS EIRELI ME | C11: 21707 | D11: 30862 | E11: 44959 | F11: 45199 | G11: 330000 | H11: 550 | I11: NOTA FISCAL Nº 30862 | J11: CLAYRTON DA SILVA | K11: BRASIL_COB
A12: CL08007 | B12: CONTINENTAL AGRONEGOCIOS EIRELI ME | C12: 21548 | D12: 30703 | E12: 44944 | F12: 45199 | G12: 270000 | H12: 550 | I12: NOTA FISCAL Nº 30703 | J12: CLAYRTON DA SILVA | K12: BRASIL_COB
A13: CL08007 | B13: CONTINENTAL AGRONEGOCIOS EIRELI ME | C13: 21711 | D13: 30866 | E13: 44959 | F13: 45199 | G13: 160000 | H13: 550 | I13: NOTA FISCAL Nº 30866 | J13: CLAYRTON DA SILVA | K13: BRASIL_COB
... A71: CL09466 | B71: A.M. GALLO COMERCIO E REPRESENTACAO DE RACAO LTDA | C71: 27649 | D71: 37427 | E71: 45596 | F71: 45716 | G71: 182520 | H71: 33 | I71: NOTA FISCAL Nº 37427 | J71: LEANDRO ALENCAR | K71: BRASIL_COB
A72: CL08971 | B72: CELSO YASUEI MIYAYACIKI | C72: 28795 | D72: 38881 | E72: 45693 | F72: 45723 | G72: 52990 | H72: 26 | I72: Notas Fiscais de Saída - CL08971 | J72: NATHALIA NAURE
A73: CL08834 | B73: AGRO ALTA COMERCIO DE INSUMOS AGRICOLAS LTDA | C73: 28070 | D73: 37992 | E73: 45638 | F73: 45728 | G73: 39199.96 | H73: 21 | I73: NOTA FISCAL Nº 37992 | J73: GABRIEL BORGES | K73: BRASIL_COB
A74: CL08834 | B74: AGRO ALTA COMERCIO DE INSUMOS AGRICOLAS LTDA | C74: 28072 | D74: 37994 | E74: 45638 | F74: 45728 | G74: 10999.99 | H74: 21 | I74: NOTA FISCAL Nº 37994 | J74: GABRIEL BORGES | K74: BRASIL_COB
A75: CL08834 | B75: AGRO ALTA COMERCIO DE INSUMOS AGRICOLAS LTDA | C75: 28075 | D75: 37997 | E75: 45638 | F75: 45728 | G75: 12909.99 | H75: 21 | I75: NOTA FISCAL Nº 37997 | J75: GABRIEL BORGES | K75: BRASIL_COB
A76: CL08834 | B76: AGRO ALTA COMERCIO DE INSUMOS AGRICOLAS LTDA | C76: 27383 | D76: 37109 | E76: 45579 | F76: 45729 | G76: 8812.5 | H76: 20 | I76: NOTA FISCAL Nº 37109 | J76: GABRIEL BORGES | K76: BRASIL_COB
A77: CL08834 | B77: AGRO ALTA COMERCIO DE INSUMOS AGRICOLAS LTDA | C77: 27384 | D77: 37110 | E77: 45579 | F77: 45729 | G77: 35515.34 | H77: 20 | I77: NOTA FISCAL Nº 37110 | J77: GABRIEL BORGES | K77: BRASIL_COB
A78: CL08834 | B78: AGRO ALTA COMERCIO DE INSUMOS AGRICOLAS LTDA | C78: 28389 | D78: 38386 | E78: 45670 | F78: 45730 | G78: 41124.96 | H78: 19 | I78: NOTA FISCAL Nº 38386 | J78: GABRIEL BORGES | K78: BRASIL_COB
A79: CL08834 | B79: AGRO ALTA COMERCIO DE INSUMOS AGRICOLAS LTDA | C79: 28452 | D79: 38449 | E79: 45672 | F79: 45733 | G79: 5731.99 | H79: 16 | I79: NOTA FISCAL Nº 38449 | J79: GABRIEL BORGES | K79: BRASIL_COB
A80: CL08834 | B80: AGRO ALTA COMERCIO DE INSUMOS AGRICOLAS LTDA | C80: 28425 | D80: 38419 | E80: 45671 | F80: 45733 | G80: 20054.98 | H80: 16 | I80: NOTA FISCAL Nº 38419 | J80: GABRIEL BORGES | K80: BRASIL_COB
A81: CL08834 | B81: AGRO ALTA COMERCIO DE INSUMOS AGRICOLAS LTDA | C81: 28198 | D81: 38139 | E81: 45646 | F81: 45736 | G81: 26234.97 | H81: 13 | I81: NOTA FISCAL Nº 38139 | J81: GABRIEL BORGES | K81: BRASIL_COB
A82: CL09761 | B82: MINAS FERTIL PRODUTOS AGRICOLA LTDA | C82: 26140 | D82: 35748 | E82: 45488 | F82: 45736 | G82: 36573.6 | H82: 13 | I82: Notas Fiscais de Saída - CL09761 | J82: MATHEUS MACEDO | K82: BRASIL_COB
A83: CL08834 | B83: AGRO ALTA COMERCIO DE INSUMOS AGRICOLAS LTDA | C83: 28197 | D83: 38138 | E83: 45646 | F83: 45736 | G83: 3863.93 | H83: 13 | I83: NOTA FISCAL Nº 38138 | J83: GABRIEL BORGES | K83: BRASIL_COB
A84: CL08834 | B84: AGRO ALTA COMERCIO DE INSUMOS AGRICOLAS LTDA | C84: 27488 | D84: 37254 | E84: 45588 | F84: 45740 | G84: 1620.34 | H84: 9 | I84: NOTA FISCAL Nº 37254 | J84: GABRIEL BORGES | K84: BRASIL_COB
... A106: CL09617 | B106: HORTAVIVA COMERCIO DE SEMENTES E INSUMOS AGRICOLAS LTDA EPP | C106: 29098 | D106: 39257 | E106: 45721 | F106: 45751 | G106: 7008.79 | H106: 0 | I106: Notas Fiscais de Saída - CL09617 | J106: LUCAS WEBER | K106: BRASIL_COB
A107: CL09734 | B107: TWS ASSESSORIA EM COMERCIO EXTERIOR E DESPACHO ADUANEIRO LTDA | D107: 273844 | E107: 45741 | F107: 45752 | G107: 124.48 | H107: 0 | I107: Valor a reembolsar TWS - 0250/24 | J107: MARIEL FELIPETTO
A108: CL08807 | B108: ECOSOLUCAO AGROCIENCIAS E SOLUCOES AMBIENTAIS LTDA | C108: 28766 | D108: 38845 | E108: 45692 | F108: 45752 | G108: 105136.5 | H108: 0 | I108: NOTA FISCAL Nº 38845 | J108: -Nenhum vendedor- | K108: BRASIL_COB
A109: CL08689 | B109: CLAUDIANA DE ALMEIDA RODRIGUES IMPORTACAO E EXPORTACAO DE FERTILIZANTES LTDA | C109: 27702 | D109: 37497 | E109: 45602 | F109: 45754 | G109: 18864.43 | H109: 0 | I109: NOTA FISCAL Nº 37497 | J109: ERICK DE OLIVEIRA | K109: BRASIL_COB
A110: CL09720 | B110: RODRIGUES & FERNANDES LTDA ME | C110: 28307 | D110: 38283 | E110: 45663 | F110: 45754 | G110: 5375.58 | H110: 0 | I110: NOTA FISCAL Nº 38283 | J110: FRANCISCO PACHECO | K110: BRASIL_COB
A111: CL08689 | B111: CLAUDIANA DE ALMEIDA RODRIGUES IMPORTACAO E EXPORTACAO DE FERTILIZANTES LTDA | C111: 28547 | D111: 38565 | E111: 45678 | F111: 45754 | G111: 13139.99 | H111: 0 | I111: Notas Fiscais de Saída - CL08689 | J111: ERICK DE OLIVEIRA | K111: BRASIL_COB
A112: CL08689 | B112: CLAUDIANA DE ALMEIDA RODRIGUES IMPORTACAO E EXPORTACAO DE FERTILIZANTES LTDA | C112: 27851 | D112: 37687 | E112: 45618 | F112: 45754 | G112: 2584.44 | H112: 0 | I112: NOTA FISCAL Nº 37687 | J112: ERICK DE OLIVEIRA | K112: BRASIL_COB
A113: CL09772 | B113: NOVA SAFRA AGRICOLA LTDA | C113: 28811 | D113: 38895 | E113: 45694 | F113: 45754 | G113: 13149 | H113: 0 | I113: Notas Fiscais de Saída - CL09772 | J113: FERNANDO GONCALVES | K113: BRASIL_COB
A114: CL08689 | B114: CLAUDIANA DE ALMEIDA RODRIGUES IMPORTACAO E EXPORTACAO DE FERTILIZANTES LTDA | C114: 27850 | D114: 37686 | E114: 45618 | F114: 45754 | G114: 3413.33 | H114: 0 | I114: NOTA FISCAL Nº 37686 | J114: ERICK DE OLIVEIRA | K114: BRASIL_COB
A115: CL08689 | B115: CLAUDIANA DE ALMEIDA RODRIGUES IMPORTACAO E EXPORTACAO DE FERTILIZANTES LTDA | C115: 28538 | D115: 38555 | E115: 45678 | F115: 45754 | G115: 1813.33 | H115: 0 | I115: Notas Fiscais de Saída - CL08689 | J115: ERICK DE OLIVEIRA | K115: BRASIL_COB
A116: CL08571 | B116: VITAGRICOLA LTDA | C116: 27337 | D116: 37056 | E116: 45574 | F116: 45754 | G116: 6363.87 | H116: 0 | I116: NOTA FISCAL Nº 37056 | J116: LUCAS FERREIRA | K116: BRASIL_COB
A117: CL08689 | B117: CLAUDIANA DE ALMEIDA RODRIGUES IMPORTACAO E EXPORTACAO DE FERTILIZANTES LTDA | C117: 27837 | D117: 37669 | E117: 45617 | F117: 45754 | G117: 7355.99 | H117: 0 | I117: NOTA FISCAL Nº 37669 | J117: ERICK DE OLIVEIRA | K117: BRASIL_COB
A118: CL06114 | B118: APOIO DISTRIBUIDORA AGRICOLA LTDA | C118: 27703 | D118: 37498 | E118: 45602 | F118: 45754 | G118: 157900 | H118: 0 | I118: NOTA FISCAL Nº 37498 | J118: LAIANE RIOS | K118: BRASIL_COB
...

Sheet TOTAL INADIMPLENTES
A1: Codigo PN | B1: Razao Social | C1: No.Docto. | D1: No. NF | E1: Emissão | F1: Vencimento | G1: Valor R$ | H1: Dias Atraso | I1: Observacoes | J1: Vendedor | K1: Forma Pagto.
A2: CL08007 | B2: CONTINENTAL AGRONEGOCIOS EIRELI ME | C2: 20750 | D2: 29860 | E2: 44844 | F2: 45076 | G2: 296573.94 | H2: 673 | I2: NOTA FISCAL Nº 29860 | J2: CLAYRTON DA SILVA | K2: BRASIL_COB
A3: CL08007 | B3: CONTINENTAL AGRONEGOCIOS EIRELI ME | C3: 20867 | D3: 29996 | E3: 44858 | F3: 45076 | G3: 104000 | H3: 673 | I3: NOTA FISCAL Nº 29996 | J3: CLAYRTON DA SILVA | K3: BRASIL_COB
A4: CL08007 | B4: CONTINENTAL AGRONEGOCIOS EIRELI ME | C4: 20847 | D4: 29968 | E4: 44854 | F4: 45076 | G4: 67036.32 | H4: 673 | I4: NOTA FISCAL Nº 29968 | J4: CLAYRTON DA SILVA | K4: BRASIL_COB
A5: CL08007 | B5: CONTINENTAL AGRONEGOCIOS EIRELI ME | C5: 21739 | D5: 30890 | E5: 44961 | F5: 45168 | G5: 22000 | H5: 581 | I5: NOTA FISCAL Nº 30890 | J5: CLAYRTON DA SILVA | K5: BRASIL_COB
A6: CL08007 | B6: CONTINENTAL AGRONEGOCIOS EIRELI ME | C6: 21546 | D6: 30701 | E6: 44944 | F6: 45168 | G6: 15600 | H6: 581 | I6: NOTA FISCAL Nº 30701 | J6: CLAYRTON DA SILVA | K6: BRASIL_COB
A7: CL08007 | B7: CONTINENTAL AGRONEGOCIOS EIRELI ME | C7: 21379 | D7: 30540 | E7: 44921 | F7: 45168 | G7: 248695 | H7: 581 | I7: NOTA FISCAL Nº 30540 | J7: CLAYRTON DA SILVA | K7: BRASIL_COB
A8: CL08007 | B8: CONTINENTAL AGRONEGOCIOS EIRELI ME | C8: 21617 | D8: 30775 | E8: 44950 | F8: 45168 | G8: 353500 | H8: 581 | I8: NOTA FISCAL Nº 30775 | J8: CLAYRTON DA SILVA | K8: BRASIL_COB
A9: CL08007 | B9: CONTINENTAL AGRONEGOCIOS EIRELI ME | C9: 21616 | D9: 30774 | E9: 44950 | F9: 45199 | G9: 335040 | H9: 550 | I9: NOTA FISCAL Nº 30774 | J9: CLAYRTON DA SILVA | K9: BRASIL_COB
A10: CL08007 | B10: CONTINENTAL AGRONEGOCIOS EIRELI ME | C10: 21740 | D10: 30891 | E10: 44961 | F10: 45199 | G10: 168960 | H10: 550 | I10: NOTA FISCAL Nº 30891 | J10: CLAYRTON DA SILVA | K10: BRASIL_COB
A11: CL08007 | B11: CONTINENTAL AGRONEGOCIOS EIRELI ME | C11: 21707 | D11: 30862 | E11: 44959 | F11: 45199 | G11: 330000 | H11: 550 | I11: NOTA FISCAL Nº 30862 | J11: CLAYRTON DA SILVA | K11: BRASIL_COB
A12: CL08007 | B12: CONTINENTAL AGRONEGOCIOS EIRELI ME | C12: 21548 | D12: 30703 | E12: 44944 | F12: 45199 | G12: 270000 | H12: 550 | I12: NOTA FISCAL Nº 30703 | J12: CLAYRTON DA SILVA | K12: BRASIL_COB
A13: CL08007 | B13: CONTINENTAL AGRONEGOCIOS EIRELI ME | C13: 21711 | D13: 30866 | E13: 44959 | F13: 45199 | G13: 160000 | H13: 550 | I13: NOTA FISCAL Nº 30866 | J13: CLAYRTON DA SILVA | K13: BRASIL_COB
... A71: CL09466 | B71: A.M. GALLO COMERCIO E REPRESENTACAO DE RACAO LTDA | C71: 27649 | D71: 37427 | E71: 45596 | F71: 45716 | G71: 182520 | H71: 33 | I71: NOTA FISCAL Nº 37427 | J71: LEANDRO ALENCAR | K71: BRASIL_COB
A72: CL08971 | B72: CELSO YASUEI MIYAYACIKI | C72: 28795 | D72: 38881 | E72: 45693 | F72: 45723 | G72: 52990 | H72: 26 | I72: Notas Fiscais de Saída - CL08971 | J72: NATHALIA NAURE
A73: CL08834 | B73: AGRO ALTA COMERCIO DE INSUMOS AGRICOLAS LTDA | C73: 28070 | D73: 37992 | E73: 45638 | F73: 45728 | G73: 39199.96 | H73: 21 | I73: NOTA FISCAL Nº 37992 | J73: GABRIEL BORGES | K73: BRASIL_COB
A74: CL08834 | B74: AGRO ALTA COMERCIO DE INSUMOS AGRICOLAS LTDA | C74: 28072 | D74: 37994 | E74: 45638 | F74: 45728 | G74: 10999.99 | H74: 21 | I74: NOTA FISCAL Nº 37994 | J74: GABRIEL BORGES | K74: BRASIL_COB
A75: CL08834 | B75: AGRO ALTA COMERCIO DE INSUMOS AGRICOLAS LTDA | C75: 28075 | D75: 37997 | E75: 45638 | F75: 45728 | G75: 12909.99 | H75: 21 | I75: NOTA FISCAL Nº 37997 | J75: GABRIEL BORGES | K75: BRASIL_COB
A76: CL08834 | B76: AGRO ALTA COMERCIO DE INSUMOS AGRICOLAS LTDA | C76: 27383 | D76: 37109 | E76: 45579 | F76: 45729 | G76: 8812.5 | H76: 20 | I76: NOTA FISCAL Nº 37109 | J76: GABRIEL BORGES | K76: BRASIL_COB
A77: CL08834 | B77: AGRO ALTA COMERCIO DE INSUMOS AGRICOLAS LTDA | C77: 27384 | D77: 37110 | E77: 45579 | F77: 45729 | G77: 35515.34 | H77: 20 | I77: NOTA FISCAL Nº 37110 | J77: GABRIEL BORGES | K77: BRASIL_COB
A78: CL08834 | B78: AGRO ALTA COMERCIO DE INSUMOS AGRICOLAS LTDA | C78: 28389 | D78: 38386 | E78: 45670 | F78: 45730 | G78: 41124.96 | H78: 19 | I78: NOTA FISCAL Nº 38386 | J78: GABRIEL BORGES | K78: BRASIL_COB
A79: CL08834 | B79: AGRO ALTA COMERCIO DE INSUMOS AGRICOLAS LTDA | C79: 28452 | D79: 38449 | E79: 45672 | F79: 45733 | G79: 5731.99 | H79: 16 | I79: NOTA FISCAL Nº 38449 | J79: GABRIEL BORGES | K79: BRASIL_COB
A80: CL08834 | B80: AGRO ALTA COMERCIO DE INSUMOS AGRICOLAS LTDA | C80: 28425 | D80: 38419 | E80: 45671 | F80: 45733 | G80: 20054.98 | H80: 16 | I80: NOTA FISCAL Nº 38419 | J80: GABRIEL BORGES | K80: BRASIL_COB
A81: CL08834 | B81: AGRO ALTA COMERCIO DE INSUMOS AGRICOLAS LTDA | C81: 28198 | D81: 38139 | E81: 45646 | F81: 45736 | G81: 26234.97 | H81: 13 | I81: NOTA FISCAL Nº 38139 | J81: GABRIEL BORGES | K81: BRASIL_COB
A82: CL09761 | B82: MINAS FERTIL PRODUTOS AGRICOLA LTDA | C82: 26140 | D82: 35748 | E82: 45488 | F82: 45736 | G82: 36573.6 | H82: 13 | I82: Notas Fiscais de Saída - CL09761 | J82: MATHEUS MACEDO | K82: BRASIL_COB
A83: CL08834 | B83: AGRO ALTA COMERCIO DE INSUMOS AGRICOLAS LTDA | C83: 28197 | D83: 38138 | E83: 45646 | F83: 45736 | G83: 3863.93 | H83: 13 | I83: NOTA FISCAL Nº 38138 | J83: GABRIEL BORGES | K83: BRASIL_COB
A84: CL08834 | B84: AGRO ALTA COMERCIO DE INSUMOS AGRICOLAS LTDA | C84: 27488 | D84: 37254 | E84: 45588 | F84: 45740 | G84: 1620.34 | H84: 9 | I84: NOTA FISCAL Nº 37254 | J84: GABRIEL BORGES | K84: BRASIL_COB
... A96: CL08834 | B96: AGRO ALTA COMERCIO DE INSUMOS AGRICOLAS LTDA | C96: 27260 | D96: 36967 | E96: 45568 | F96: 45748 | G96: 493.9 | H96: 1 | I96: NOTA FISCAL Nº 36967 | J96: GABRIEL BORGES | K96: BRASIL_COB

Sheet ANALISE INADIMPLENCIA
A3: CLIENTES | B3: Soma de Valor R$ | C3: Máx. de Dias Atraso | D3: VENDEDOR | E3: STATUS DA COBRANÇA | F3: NEGOCIAÇÃO | G3: PROVIDENCIA
A4: A.M. GALLO COMERCIO E REPRESENTACAO DE RACAO LTDA | B4: 182520 | C4: 33 | D4: =VLOOKUP(A4,'TOTAL EM ABERTO'!B2:J96,9,FALSE) -> LEANDRO ALENCAR | E4: =IFERROR(VLOOKUP(A4,'[1]ANALISE INADIMPLENCIA'!$A$4:$E$19,5,FALSE),"-") -> CLIENTE EM RECUPERAÇAO JUDICIAL, AGUARDANDO SAIR A APROVAÇÃO DA RECUPERAÇÃO JUDICIAL, ESTÁ PENDENTE ENTRAR EM CONTATO COM OS DEVEDORES DAS DUPLICATAS ENDOSSADAS QUE TIVEREM DUVIDAS SOBRE O PAGAMENTO, CLIENTE SE COMPROMETEU A AUXILIAR NO RECEBIMENTO DAS DUPLICATAS ENDOSSADAS, AO QUAL VAI PAGAR AOS CLIENTES O VALOR DOS PRODUTOS QUE NÃO FORAM ENTREGUES, PARA QUE O BOLETO DO ENDOSSO PARA A COMPO SEJA PAGO INTEGRALMENTE | F4: =IFERROR(VLOOKUP(A4,'[1]ANALISE INADIMPLENCIA'!$A$4:$F$19,6,FALSE),"-") -> - | G4: =IFERROR(VLOOKUP(A4,'[1]ANALISE INADIMPLENCIA'!$A$15:$G$19,7,FALSE),"-") -> -
A5: ADRIANA DA SILVA RUBIN | B5: 39600 | C5: 3 | D5: =VLOOKUP(A5,'TOTAL EM ABERTO'!B3:J97,9,FALSE) -> MARYANNA SILVEIRA | E5: =IFERROR(VLOOKUP(A5,'[1]ANALISE INADIMPLENCIA'!$A$4:$E$19,5,FALSE),"-") -> - | F5: =IFERROR(VLOOKUP(A5,'[1]ANALISE INADIMPLENCIA'!$A$4:$F$19,6,FALSE),"-") -> - | G5: =IFERROR(VLOOKUP(A5,'[1]ANALISE INADIMPLENCIA'!$A$15:$G$19,7,FALSE),"-") -> -
A6: AGRO ALTA COMERCIO DE INSUMOS AGRICOLAS LTDA | B6: 214562.85 | C6: 21 | D6: =VLOOKUP(A6,'TOTAL EM ABERTO'!B4:J98,9,FALSE) -> GABRIEL BORGES | E6: =IFERROR(VLOOKUP(A6,'[1]ANALISE INADIMPLENCIA'!$A$4:$E$19,5,FALSE),"-") -> SOLICITADO AO JURÍDICO CONFISSÃO DE DÍVIDA PRORROGANDO OS PAGAMENTOS EM ABERTO COM A METADE PARA PAGAMENTO EM 15 DIAS E A OUTRA METADE PARA 3O DIAS, O PRIMEIRO PAGAMENTO É PARA DIA 17/03. NOVAS VENDAS NESTE PERÍODO SOMENTE A VISTA. | F6: =IFERROR(VLOOKUP(A6,'[1]ANALISE INADIMPLENCIA'!$A$4:$F$19,6,FALSE),"-") -> - | G6: =IFERROR(VLOOKUP(A6,'[1]ANALISE INADIMPLENCIA'!$A$15:$G$19,7,FALSE),"-") -> -
A7: ANTONIO CARLOS RIBEIRO | B7: 200630 | C7: 124 | D7: =VLOOKUP(A7,'TOTAL EM ABERTO'!B5:J99,9,FALSE) -> CESAR CAIXETA | E7: =IFERROR(VLOOKUP(A7,'[1]ANALISE INADIMPLENCIA'!$A$4:$E$19,5,FALSE),"-") -> CONFISSÃO DE DÍVIDA ASSINADA, COM FILHO E ESPOSA COMO FIADORES DA RENEGOCIAÇÃO | F7: =IFERROR(VLOOKUP(A7,'[1]ANALISE INADIMPLENCIA'!$A$4:$F$19,6,FALSE),"-") -> PAGAMENTO EM 6 PARCELAS: 02/12 (PAGA), 06/01/2025 (PAGA), 03/02/2025 (PAGO), 03/03/2025 (PAGO), 03/04/2025 e 02/05/2025 | G7: =IFERROR(VLOOKUP(A7,'[1]ANALISE INADIMPLENCIA'!$A$15:$G$19,7,FALSE),"-") -> -
A8: BRUNO RUBIN STEFANELLO | B8: 178200 | C8: 3 | D8: =VLOOKUP(A8,'TOTAL EM ABERTO'!B6:J100,9,FALSE) -> MARYANNA SILVEIRA | E8: =IFERROR(VLOOKUP(A8,'[1]ANALISE INADIMPLENCIA'!$A$4:$E$19,5,FALSE),"-") -> - | F8: =IFERROR(VLOOKUP(A8,'[1]ANALISE INADIMPLENCIA'!$A$4:$F$19,6,FALSE),"-") -> - | G8: =IFERROR(VLOOKUP(A8,'[1]ANALISE INADIMPLENCIA'!$A$15:$G$19,7,FALSE),"-") -> -
A9: CARLOS STEFANELLO | B9: 69300 | C9: 3 | D9: =VLOOKUP(A9,'TOTAL EM ABERTO'!B7:J101,9,FALSE) -> MARYANNA SILVEIRA | E9: =IFERROR(VLOOKUP(A9,'[1]ANALISE INADIMPLENCIA'!$A$4:$E$19,5,FALSE),"-") -> - | F9: =IFERROR(VLOOKUP(A9,'[1]ANALISE INADIMPLENCIA'!$A$4:$F$19,6,FALSE),"-") -> - | G9: =IFERROR(VLOOKUP(A9,'[1]ANALISE INADIMPLENCIA'!$A$15:$G$19,7,FALSE),"-") -> -
A10: CELSO YASUEI MIYAYACIKI | B10: 52990 | C10: 26 | D10: =VLOOKUP(A10,'TOTAL EM ABERTO'!B8:J102,9,FALSE) -> NATHALIA NAURE | E10: =IFERROR(VLOOKUP(A10,'[1]ANALISE INADIMPLENCIA'!$A$4:$E$19,5,FALSE),"-") -> AGUARDANDO LIBERAÇAO DO CRÉDITO DE ICMS | F10: =IFERROR(VLOOKUP(A10,'[1]ANALISE INADIMPLENCIA'!$A$4:$F$19,6,FALSE),"-") -> - | G10: =IFERROR(VLOOKUP(A10,'[1]ANALISE INADIMPLENCIA'!$A$15:$G$19,7,FALSE),"-") -> -
A11: CONTINENTAL AGRONEGOCIOS EIRELI ME | B11: 2371405.3 | C11: 673 | D11: =VLOOKUP(A11,'TOTAL EM ABERTO'!B9:J103,9,FALSE) -> CLAYRTON DA SILVA | E11: =IFERROR(VLOOKUP(A11,'[1]ANALISE INADIMPLENCIA'!$A$4:$E$19,5,FALSE),"-") -> GARANTIA HIPOTECÁRIA PERMANECE EM 1 E 2º GRAU PARA O BANCO DO BRASIL. INFORMADO AO JURÍDICO PARA INICIAR PROCESSO DE COBRANÇA JUDICIAL, SOLICITADO AO JURÍDICO VERIFICAR SE HÁ ALGUM IMPEDIMENTO PARA SEGUIRMOS COM A EXECUÇÃO DEVIDO A TERMOS VOTADO FAVORÁVEL AO PLANO DA RJ, JURÍDICO RETORNOU QUE NO MOMENTO NÃO PODEMOS EXECUTAR A GARANTIA POR TERMOS VOTADO FAVORÁVEL AO PRJ, SOMENTE SE FOR DECRETADO FALENCIA VOLTAREMOS A TER DIREITO À EXECUÇÃO. CLAYRTON ESTÁ TENTANDO NEGOCIAR COM O LUIZ PAULO UMA GARANTIA DE CESSÃO DE CRÉDITO, PORÉM IREMOS RETORMAR ESSA CONVERSA SOMENTE NA SEGUNDA QUINZENA DE FEVEREIRO, POIS SERIA UMA CESSÃO DE CRÉDITO PARA MILHO | F11: =IFERROR(VLOOKUP(A11,'[1]ANALISE INADIMPLENCIA'!$A$4:$F$19,6,FALSE),"-") -> - | G11: =IFERROR(VLOOKUP(A11,'[1]ANALISE INADIMPLENCIA'!$A$15:$G$19,7,FALSE),"-") -> -
A12: FM AGRICOLA VICOSA LTDA | B12: 7021.67 | C12: 2 | D12: =VLOOKUP(A12,'TOTAL EM ABERTO'!B10:J104,9,FALSE) -> LUCAS FERREIRA | E12: =IFERROR(VLOOKUP(A12,'[1]ANALISE INADIMPLENCIA'!$A$4:$E$19,5,FALSE),"-") -> - | F12: =IFERROR(VLOOKUP(A12,'[1]ANALISE INADIMPLENCIA'!$A$4:$F$19,6,FALSE),"-") -> - | G12: =IFERROR(VLOOKUP(A12,'[1]ANALISE INADIMPLENCIA'!$A$15:$G$19,7,FALSE),"-") -> -
A13: LEONARDO SANFELICE EITELWEIN | B13: 64190 | C13: 2 | D13: =VLOOKUP(A13,'TOTAL EM ABERTO'!B11:J105,9,FALSE) -> CARLOS BERNARDES | E13: =IFERROR(VLOOKUP(A13,'[1]ANALISE INADIMPLENCIA'!$A$4:$E$19,5,FALSE),"-") -> - | F13: =IFERROR(VLOOKUP(A13,'[1]ANALISE INADIMPLENCIA'!$A$4:$F$19,6,FALSE),"-") -> - | G13: =IFERROR(VLOOKUP(A13,'[1]ANALISE INADIMPLENCIA'!$A$15:$G$19,7,FALSE),"-") -> -
A14: MINAS FERTIL PRODUTOS AGRICOLA LTDA | B14: 36573.6 | C14: 13 | D14: =VLOOKUP(A14,'TOTAL EM ABERTO'!B12:J106,9,FALSE) -> MATHEUS MACEDO | E14: =IFERROR(VLOOKUP(A14,'[1]ANALISE INADIMPLENCIA'!$A$4:$E$19,5,FALSE),"-") -> CLIENTE TEM 5 M BRL EM NEGATIVAÇÕES NO SERASA, SÓCIOS TEM 4 M BRL EM NEGATIVAÇÕES COMO AVALISTAS, DIVIDAS DA IHARA, REUNIAO MARCADA COM JULIO E MATHEUS PARA FALARMOS SOBRE A SITUAÇAO DO CLIENTE, POIS CLIENTE SOLICITOU DEVOLUÇÃO DE PRODUTOS E PRORROGAÇAO DESTE PAGAMENTO PARA 30/04. A PRINCÍPIO TEM 51 MIL EM ESTOQUE DE PRODUTOS COMPO, EXPOSIÇÃO DE 165 MIL, PROXIMOS VENCIMENTOS 107 MIL EM 20/05 E 21 MIL EM 20/07 | F14: =IFERROR(VLOOKUP(A14,'[1]ANALISE INADIMPLENCIA'!$A$4:$F$19,6,FALSE),"-") -> - | G14: =IFERROR(VLOOKUP(A14,'[1]ANALISE INADIMPLENCIA'!$A$15:$G$19,7,FALSE),"-") -> -
A15: MOGIANA NEGOCIOS AGROPECUARIO LTDA | B15: 4538138.7 | C15: 347 | D15: =VLOOKUP(A15,'TOTAL EM ABERTO'!B13:J107,9,FALSE) -> GABRIEL BORGES | E15: =IFERROR(VLOOKUP(A15,'[1]ANALISE INADIMPLENCIA'!$A$4:$E$19,5,FALSE),"-") -> ENCAMINHADO PARA EXECUÇÃO JUDICIAL AS DUPLICATAS DO KASSIO E OS VEÍCULOS EM GARANTIA DA MOGIANA. ESTÁ EM NEGOCIAÇÃO AS MÁQUINAS, PENDENTE DE ASSINATURA. | F15: =IFERROR(VLOOKUP(A15,'[1]ANALISE INADIMPLENCIA'!$A$4:$F$19,6,FALSE),"-") -> - | G15: =IFERROR(VLOOKUP(A15,'[1]ANALISE INADIMPLENCIA'!$A$15:$G$19,7,FALSE),"-") -> NEGOCIAR AS MÁQUINAS E AGUARDAR PAGAMENTO NA SEGUNDA PARCELA PARA FORMALIZAR O ACORDO
... A17: PRODUFERTIL COMERCIO DE PRODUTOS AGRICOLAS LTDA | B17: 2464871.9 | C17: 215 | D17: =VLOOKUP(A17,'TOTAL EM ABERTO'!B15:J109,9,FALSE) -> CARLOS BERNARDES | E17: =IFERROR(VLOOKUP(A17,'[1]ANALISE INADIMPLENCIA'!$A$4:$E$19,5,FALSE),"-") -> SEGURO DE CRÉDITO ACIONADO, COBERTURA DE 2 M BRL. CONFISSÃO DE DÍVIDA ASSINADA PARA PAGAMENTO EM 25/03/2025, COM A GARANTIA DA CESSÃO DE CRÉDITO PARA A MESMA DATA. ACOMPANHAR JUNTO AO CLIENTE E VENDEDOR A ENTREGA DOS GRÃOS DA CESSÃO DE CRÉDITO, PERÍODO DE ENTREGA DOS GRÃOS DA CESSÃO DE 01/02/2025 a 28/02/2025 | F17: =IFERROR(VLOOKUP(A17,'[1]ANALISE INADIMPLENCIA'!$A$4:$F$19,6,FALSE),"-") -> - | G17: =IFERROR(VLOOKUP(A17,'[1]ANALISE INADIMPLENCIA'!$A$15:$G$19,7,FALSE),"-") -> AGUARDANDO PAGAMENTO.
A18: SERGIO EITELWEIN | B18: 126715 | C18: 2 | D18: =VLOOKUP(A18,'TOTAL EM ABERTO'!B16:J110,9,FALSE) -> CARLOS BERNARDES | E18: CONFISSÃO DE DÍVIDA ASSINADA | F18: PAGAMENTO NO DIA 22/04/2025 | G18: AGUARDANDO PAGAMENTO.
A19: Total Geral | B19: 10579100 | C19: 673
A20: Total em aberto | B20: =SUM(Tabela1[Valor R$]) -> 1.1823171e+08
A21: Taxa de inadimplencia | B21: =GETPIVOTDATA("Soma de Valor R$",$A$3)/B20 -> 0.089477689
